<robot
  name="tilt">
  <link
    name="corpo">
    <inertial>
      <origin
        xyz="0.00256429700632625 -0.00177063953172816 -0.0184675483937402"
        rpy="0 0 0" />
      <mass
        value="1.908310289141" />
      <inertia
        ixx="0.0684037032869774"
        ixy="5.36618171598915E-05"
        ixz="-0.000361771022313387"
        iyy="0.00789097264105409"
        iyz="-0.000218363389363015"
        izz="0.0650790672422852" />
    </inertial>
    <visual>
      <origin
        xyz="0 0 0"
        rpy="0 0 0" />
      <geometry>
        <mesh
          filename="package://tilt/meshes/corpo.STL" />
      </geometry>
      <material
        name="">
        <color
          rgba="0.792156862745098 0.819607843137255 0.933333333333333 1" />
      </material>
    </visual>
    <collision>
      <origin
        xyz="0 0 0"
        rpy="0 0 0" />
      <geometry>
        <mesh
          filename="package://tilt/meshes/corpo.STL" />
      </geometry>
    </collision>
  </link>
  <link
    name="servodir">
    <inertial>
      <origin
        xyz="-1.64500973065911E-05 -0.000256941591331994 0.0561664766143311"
        rpy="0 0 0" />
      <mass
        value="0.0713136390603168" />
      <inertia
        ixx="3.14771600689694E-05"
        ixy="1.2649483825246E-09"
        ixz="-4.92425079055472E-09"
        iyy="3.02767255246939E-05"
        iyz="6.44165288529201E-07"
        izz="1.44224289717711E-05" />
    </inertial>
    <visual>
      <origin
        xyz="0 0 0"
        rpy="0 0 0" />
      <geometry>
        <mesh
          filename="package://tilt/meshes/servodir.STL" />
      </geometry>
      <material
        name="">
        <color
          rgba="0.647058823529412 0.619607843137255 0.588235294117647 1" />
      </material>
    </visual>
    <!--<collision>
      <origin
        xyz="0 0 0"
        rpy="0 0 0" />
      <geometry>
        <mesh
          filename="package://tilt/meshes/servodir.STL" />
      </geometry>
    </collision>-->
  </link>
  <joint
    name="aR"
    type="revolute">
    <origin
      xyz="-1.8271804286945E-05 -0.277611425055307 0.0549286993075094"
      rpy="-0.0261799241453877 0.000147944076641961 9.98008905062241E-05" />
    <parent
      link="corpo" />
    <child
      link="servodir" />
    <axis
      xyz="-9.98351002423385E-05 -0.999999995016477 0" />
    <limit
      lower="-1"
      upper="1"
      effort="10"
      velocity="10" />
  </joint>
  <link
    name="helicedir">
    <inertial>
      <origin
        xyz="-4.0634359135816E-07 6.58528663266544E-08 3.43719603196346E-07"
        rpy="0 0 0" />
      <mass
        value="0.00963319741474509" />
      <inertia
        ixx="1.308397044181E-06"
        ixy="-8.47880273863235E-06"
        ixz="1.9877604516713E-08"
        iyy="6.74789344924412E-05"
        iyz="-2.50764833601657E-09"
        izz="6.8755269236743E-05" />
    </inertial>
    <visual>
      <origin
        xyz="0 0 0"
        rpy="0 0 0" />
      <geometry>
        <mesh
          filename="package://tilt/meshes/helicedir.STL" />
      </geometry>
      <material
        name="">
        <color
          rgba="0 0 0.501960784313725 1" />
      </material>
    </visual>
    <!--<collision>
      <origin
        xyz="0 0 0"
        rpy="0 0 0" />
      <geometry>
        <mesh
          filename="package://tilt/meshes/helicedir.STL" />
      </geometry>
    </collision>-->
  </link>
  <joint
    name="thrustdir"
    type="continuous">
    <origin
      xyz="-2.45642483141821E-05 0 0.0839999964083198"
      rpy="3.46944695195361E-18 -8.67361737988404E-19 0.144577399017787" />
    <parent
      link="servodir" />
    <child
      link="helicedir" />
    <axis
      xyz="-0.000289376348141932 4.21607435364194E-05 0.9999999572419" />
    <limit
      lower="-1"
      upper="1"
      effort="10"
      velocity="10" />
  </joint>
  <link
    name="servoesq">
    <inertial>
      <origin
        xyz="-2.82612327927832E-08 0.000256943227470385 0.0561664790038414"
        rpy="0 0 0" />
      <mass
        value="0.0713136390866666" />
      <inertia
        ixx="3.1477162082576E-05"
        ixy="1.20327524589434E-09"
        ixz="7.10577313122764E-11"
        iyy="3.02767250419788E-05"
        iyz="-6.44164425496491E-07"
        izz="1.44224275166197E-05" />
    </inertial>
    <visual>
      <origin
        xyz="0 0 0"
        rpy="0 0 0" />
      <geometry>
        <mesh
          filename="package://tilt/meshes/servoesq.STL" />
      </geometry>
      <material
        name="">
        <color
          rgba="0.647058823529412 0.619607843137255 0.588235294117647 1" />
      </material>
    </visual>
    <!--<collision>
      <origin
        xyz="0 0 0"
        rpy="0 0 0" />
      <geometry>
        <mesh
          filename="package://tilt/meshes/servoesq.STL" />
      </geometry>
    </collision>-->
  </link>
  <joint
    name="aL"
    type="revolute">
    <origin
      xyz="0.000774317061806635 0.277601419719204 0.0549353011331433"
      rpy="0.0264243899580086 -0.000142465393102244 -0.000108408934057588" />
    <parent
      link="corpo" />
    <child
      link="servoesq" />
    <axis
      xyz="-0.000108446791897333 0.999999994119647 0" />
    <limit
      lower="-1"
      upper="1"
      effort="10"
      velocity="10" />
  </joint>
  <link
    name="heliceesq">
    <inertial>
      <origin
        xyz="-4.03612904903428E-07 -5.57232281428455E-08 3.43842413264017E-07"
        rpy="0 0 0" />
      <mass
        value="0.00963319729836474" />
      <inertia
        ixx="2.27163710542979E-06"
        ixy="1.160606543528E-05"
        ixz="3.54072262575423E-12"
        iyy="6.65156885018562E-05"
        iyz="9.15946817171114E-13"
        izz="6.87552750096705E-05" />
    </inertial>
    <visual>
      <origin
        xyz="0 0 0"
        rpy="0 0 0" />
      <geometry>
        <mesh
          filename="package://tilt/meshes/heliceesq.STL" />
      </geometry>
      <material
        name="">
        <color
          rgba="0 0 0.501960784313725 1" />
      </material>
    </visual>
    <!--<collision>
      <origin
        xyz="0 0 0"
        rpy="0 0 0" />
      <geometry>
        <mesh
          filename="package://tilt/meshes/heliceesq.STL" />
      </geometry>
    </collision>-->
  </link>
  <joint
    name="thrustesq"
    type="continuous">
    <origin
      xyz="0 0 0.0840000000000002"
      rpy="-3.33066907387547E-16 9.873178663522E-15 -0.154008614760551" />
    <parent
      link="servoesq" />
    <child
      link="heliceesq" />
    <axis
      xyz="0 0 1" />
    <limit
      lower="-1"
      upper="1"
      effort="10"
      velocity="10" />
  </joint>


	
  	<gazebo>
	    	<plugin name="quadrotor_imu_sim" filename="libhector_gazebo_ros_imu.so">
	      		<updateRate>100.0</updateRate>
	      		<bodyName>corpo</bodyName>
	      		<frameId>corpo</frameId>
	      		<topicName>raw_imu</topicName>
	      		<rpyOffsets>0 0 0</rpyOffsets> 
	      		<gaussianNoise>0</gaussianNoise>  
	      		<accelDrift>0.5 0.5 0.5</accelDrift>
	      		<accelGaussianNoise>0.35 0.35 0.3</accelGaussianNoise>
	      		<rateDrift>0.1 0.1 0.1</rateDrift>
	      		<rateGaussianNoise>0.05 0.05 0.015</rateGaussianNoise>
	    	</plugin>
	</gazebo>

	<gazebo>
		<plugin name="quadrotor_magnetic_sim" filename="libhector_gazebo_ros_magnetic.so">
	      		<updateRate>10.0</updateRate>
	      		<bodyName>corpo</bodyName>
	      		<frameId>corpo</frameId>
	      		<topicName>magnetic</topicName>
	      		<offset>0 0 0</offset>
	      		<drift>0.0 0.0 0.0</drift>
	      		<gaussianNoise>1.3e-2 1.3e-2 1.3e-2</gaussianNoise>
		</plugin>
	</gazebo>

	<gazebo>
		<plugin name="quadrotor_gps_sim" filename="libhector_gazebo_ros_gps.so">
	      		<updateRate>4.0</updateRate>
	      		<bodyName>corpo</bodyName>
	      		<frameId>corpo</frameId>
	      		<topicName>gps</topicName>
	      		<velocityTopicName>fix_velocity</velocityTopicName>
	      		<referenceLatitude>0</referenceLatitude>
	      		<referenceLongitude>0</referenceLongitude>
	      		<drift>5.0 5.0 5.0</drift>
	      		<gaussianNoise>0.01 0.01 0.01</gaussianNoise>
	      		<velocityDrift>0 0 0</velocityDrift>
	      		<velocityGaussianNoise>0.05 0.05 0.05</velocityGaussianNoise>
		</plugin>
	</gazebo>

    	<link name="ultrassom_link">
      		<inertial>
        		<mass value="0.001" />
        		<origin xyz="0 0 0" rpy="0 0 0" />
        		<inertia ixx="0.000000017" ixy="0" ixz="0" iyy="0.000000017" iyz="0" izz="0.000000017" />
      		</inertial>
      		<visual>
        		<origin xyz="0 0 0" rpy="0 0 0" />
        		<geometry>
          			<mesh filename="package://hector_sensors_description/meshes/sonar_sensor/max_sonar_ez4.dae"/>
        		</geometry>
      		</visual>
    	</link>

    	<joint name="ultrassom_joint" type="fixed">
      		<origin xyz="0 0 -0.12" rpy="0 1.57 0" />
      		<parent link="corpo"/>
      		<child link="ultrassom_link"/>
    	</joint>

    	<gazebo reference="ultrassom_link">
      		<sensor type="ray" name="ultrassom">
        		<always_on>true</always_on>
        		<update_rate>100</update_rate>
        		<pose>0 0 0 0 0 0</pose>
        		<visualize>false</visualize>
        		<ray>
          			<scan>
            				<horizontal>
              					<samples>100</samples>
              					<resolution>1</resolution>
              					<min_angle>-1</min_angle>
              					<max_angle> 1</max_angle>
            				</horizontal>
            				<vertical>
              					<samples>100</samples>
              					<resolution>1</resolution>
              					<min_angle>-1</min_angle>
              					<max_angle> 1</max_angle>
            				</vertical>
          			</scan>
         			<range>
            				<min>10</min>
            				<max>50</max>
            				<resolution>0.01</resolution>
          			</range>
        		</ray>
	

        	<plugin name="gazebo_ros_ultrassom_controller" filename="libhector_gazebo_ros_sonar.so">
          		<gaussianNoise>0.005</gaussianNoise>
          		<topicName>ultrassom</topicName>
          		<frameId>ultrassom_link</frameId>
        	</plugin>
      		</sensor>

	</gazebo>

 	<gazebo>
		<plugin name="thrustleftteste" filename="libservo_motor_plugin.so">
			<NameOfNode> Tilt </NameOfNode>	
			<NameOfJoint> thrustesq </NameOfJoint>
			<TopicSubscriber> RefThrustesq </TopicSubscriber>
			<TopicPublisher>  SensorThrustesq </TopicPublisher>
			<Kpx> 0.01 </Kpx>
			<Kpv> 0.01 </Kpv>
			<Kix> 0.01 </Kix>
			<Kiv> 0.01 </Kiv>
			<Kdx> 0.01 </Kdx>
			<Kdv> 0.01 </Kdv>
			<Modo> Velocidade </Modo>
		</plugin>
	</gazebo>	

	<gazebo>
		<plugin name="thrustrightteste" filename="libservo_motor_plugin.so">
			<NameOfNode> Tilt </NameOfNode>
			<NameOfJoint> thrustdir </NameOfJoint>
			<TopicSubscriber> RefThrustdir </TopicSubscriber>
			<TopicPublisher> SensorThrustdir </TopicPublisher>
			<Kpx> 0.01 </Kpx>
			<Kpv> 0.01 </Kpv>
			<Kix> 0.01 </Kix>
			<Kiv> 0.01 </Kiv>
			<Kdx> 0.01 </Kdx>
			<Kdv> 0.01 </Kdv>
			<Modo> Velocidade </Modo>
		</plugin>
	</gazebo>

	<gazebo>
		<plugin name="aLteste" filename="libservo_motor_plugin.so">
			<NameOfNode> Tilt </NameOfNode>	
			<NameOfJoint> aL </NameOfJoint>
			<TopicSubscriber> RefaL </TopicSubscriber>
			<TopicPublisher>  SensoraL </TopicPublisher>
			<Kpx> 4 </Kpx>
			<Kpv> 0.01 </Kpv>
			<Kix> 0 </Kix>
			<Kiv> 0 </Kiv>
			<Kdx> 0.01 </Kdx>
			<Kdv> 0.01 </Kdv>
			<Modo> Posição </Modo>
		</plugin>
	</gazebo>	

	<gazebo>
		<plugin name="aRteste" filename="libservo_motor_plugin.so">
			<NameOfNode> Tilt </NameOfNode>	
			<NameOfJoint> aR </NameOfJoint>
			<TopicSubscriber> RefaR </TopicSubscriber>
			<TopicPublisher>  SensoraR </TopicPublisher>
			<Kpx> 4 </Kpx>
			<Kpv> 0.01 </Kpv>
			<Kix> 0 </Kix>
			<Kiv> 0 </Kiv>
			<Kdx> 0.01 </Kdx>
			<Kdv> 0.01 </Kdv>
			<Modo> Posição </Modo>
		</plugin>
	</gazebo>

	<gazebo>
		<plugin name="propeller_direito" filename="libaerodinamica_plugin.so">
			<ka> 1 </ka>
			<kb> 1 </kb>
			<topic_VR> /Tilt/SensorThrustdir </topic_VR>
			<topic_VL> /Tilt/SensorThrustesq </topic_VL>
			<NameOfNode> propeller_direito </NameOfNode>
			<LinkDir> helicedir </LinkDir>
			<LinkEsq> heliceesq </LinkEsq>					
    		</plugin>
	</gazebo>

</robot>
