<robot
  name="tilt">
  <link
    name="corpo">
    <inertial>
      <origin
        xyz="-0.00178550564624431 0.000466514809170893 0.0275264262167568"
        rpy="0 0 0" />
      <mass
        value="1.92834614495378" />
      <inertia
        ixx="0.0700559603485899"
        ixy="4.81171313278652E-05"
        ixz="-0.000363018580013146"
        iyy="0.0079454505923938"
        iyz="1.07744164658085E-05"
        izz="0.0666837547078567" />
    </inertial>
    <visual>
      <origin
        xyz="0 0 0"
        rpy="0 0 0" />
      <geometry>
        <mesh
          filename="package://tilt/meshes/corpo.STL" />
      </geometry>
      <material
        name="">
        <color
          rgba="0.752941176470588 0.752941176470588 0.752941176470588 1" />
      </material>
    </visual>
    <collision>
      <origin
        xyz="0 0 0"
        rpy="0 0 0" />
      <geometry>
        <mesh
          filename="package://tilt/meshes/corpo.STL" />
      </geometry>
    </collision>
  </link>
  <link
    name="servoesq">
    <inertial>
      <origin
        xyz="-1.60574354333975E-09 0.000256950433774827 0.0561664973151414"
        rpy="0 0 0" />
      <mass
        value="0.071313642110537" />
      <inertia
        ixx="3.1477131317969E-05"
        ixy="1.33384791633858E-09"
        ixz="1.88188479012321E-13"
        iyy="3.02766998172739E-05"
        iyz="-6.44185191645591E-07"
        izz="1.44224275665651E-05" />
    </inertial>
    <visual>
      <origin
        xyz="0 0 0"
        rpy="0 0 0" />
      <geometry>
        <mesh
          filename="package://tilt/meshes/servoesq.STL" />
      </geometry>
      <material
        name="">
        <color
          rgba="0.529411764705882 0.549019607843137 0.549019607843137 1" />
      </material>
    </visual>
    <!--<collision>
      <origin
        xyz="0 0 0"
        rpy="0 0 0" />
      <geometry>
        <mesh
          filename="package://tilt/meshes/servoesq.STL" />
      </geometry>
    </collision>-->
  </link>
  <joint
    name="aL"
    type="revolute">
    <origin
      xyz="-0.00355649276858555 0.278215496595548 0.100523302768374"
      rpy="0.0261844653212001 -0.0185928637494992 -0.000483121778388988" />
    <parent
      link="corpo" />
    <child
      link="servoesq" />
    <axis
      xyz="0 0.999999999985527 0" />
    <limit
      lower="-6"
      upper="6"
      effort="10"
      velocity="10" />
  </joint>
  <link
    name="heliceesq">
    <inertial>
      <origin
        xyz="-2.97080082078353E-07 -1.52559642696559E-08 0.0840004582128408"
        rpy="0 0 0" />
      <mass
        value="0.00963022071477903" />
      <inertia
        ixx="2.64457172832474E-07"
        ixy="1.31373492851671E-06"
        ixz="6.06905473716744E-11"
        iyy="6.85205614800688E-05"
        iyz="3.53879230066552E-12"
        izz="6.87529820553705E-05" />
    </inertial>
    <visual>
      <origin
        xyz="0 0 0"
        rpy="0 0 0" />
      <geometry>
        <mesh
          filename="package://tilt/meshes/heliceesq.STL" />
      </geometry>
      <material
        name="">
        <color
          rgba="0 0 0.501960784313725 1" />
      </material>
    </visual>
    <!--<collision>
      <origin
        xyz="0 0 0"
        rpy="0 0 0" />
      <geometry>
        <mesh
          filename="package://tilt/meshes/heliceesq.STL" />
      </geometry>
    </collision>-->
  </link>
  <joint
    name="thurstesq"
    type="continuous">
    <origin
      xyz="0 0 0"
      rpy="3.46944695195361E-18 -3.46944695195361E-18 -1.0842021724855E-19" />
    <parent
      link="servoesq" />
    <child
      link="heliceesq" />
    <axis
      xyz="0 0 1" />
  </joint>
  <link
    name="servodir">
    <inertial>
      <origin
        xyz="-7.78071906854841E-05 -0.000336137262099523 0.0562769139310356"
        rpy="0 0 0" />
      <mass
        value="0.0709329033977977" />
      <inertia
        ixx="3.1227909266214E-05"
        ixy="-8.05238421134306E-08"
        ixz="1.14139449013983E-07"
        iyy="3.00303550561414E-05"
        iyz="7.60349413894601E-07"
        izz="1.42582944933191E-05" />
    </inertial>
    <visual>
      <origin
        xyz="0 0 0"
        rpy="0 0 0" />
      <geometry>
        <mesh
          filename="package://tilt/meshes/servodir.STL" />
      </geometry>
      <material
        name="">
        <color
          rgba="0.529411764705882 0.549019607843137 0.549019607843137 1" />
      </material>
    </visual>
    <!--<collision>
      <origin
        xyz="0 0 0"
        rpy="0 0 0" />
      <geometry>
        <mesh
          filename="package://tilt/meshes/servodir.STL" />
      </geometry>
    </collision>-->
  </link>
  <joint
    name="aR"
    type="revolute">
    <origin
      xyz="-0.00434908257730353 -0.277007353402455 0.100523186479296"
      rpy="-0.0261800852026307 -0.0033472956926336 9.14579673019161E-05" />
    <parent
      link="corpo" />
    <child
      link="servodir" />
    <axis
      xyz="0 -0.999999999985527 0" />
    <limit
      lower="-6"
      upper="6"
      effort="10"
      velocity="10" />
  </joint>
  <link
    name="helicedir">
    <inertial>
      <origin
        xyz="2.74886094247216E-09 -5.15232301268043E-11 0.084000455518564"
        rpy="0 0 0" />
      <mass
        value="0.00963033406162666" />
      <inertia
        ixx="7.75851122179106E-07"
        ixy="6.0308571251668E-06"
        ixz="2.02168085412147E-12"
        iyy="6.80087601560707E-05"
        iyz="3.84118734448097E-13"
        izz="6.87525702816846E-05" />
    </inertial>
    <visual>
      <origin
        xyz="0 0 0"
        rpy="0 0 0" />
      <geometry>
        <mesh
          filename="package://tilt/meshes/helicedir.STL" />
      </geometry>
      <material
        name="">
        <color
          rgba="0 0 0.501960784313725 1" />
      </material>
    </visual>
    <!--<collision>
      <origin
        xyz="0 0 0"
        rpy="0 0 0" />
      <geometry>
        <mesh
          filename="package://tilt/meshes/helicedir.STL" />
      </geometry>
    </collision>-->
  </link>
  <joint
    name="thurstdir"
    type="continuous">
    <origin
      xyz="0 0 0"
      rpy="0 0 1.35525271560688E-20" />
    <parent
      link="servodir" />
    <child
      link="helicedir" />
    <axis
      xyz="0 0 1" />
  </joint>
</robot>
